Workbook

Sheet Sheet1
A1: Name | B1: C | C1: Customer | D1: License Plate | E1: Vehicle | F1: first_payment | G1: Rent Cost | H1: Recurring Cost | I1: Cost Frequency | J1: Fleet Brand | K1: Fleet Color | L1: Rent Start Date | M1: Rent End Date | N1: State
A2: RENT/2023/0001 | B2: Mr Yan Yue Peng | C2: =TRIM(B2) -> Mr Yan Yue Peng | D2: 1I/4365 | E2: =VLOOKUP(D2, Sheet2!A:C, 3, FALSE) -> Toyota/Alphard/1I/4365 | F2: 0 | G2: 0 | H2: 1600000 | I2: Monthly | L2: 45191 | M2: 2024-04-21 | N2: Running
A3: RENT/2023/0002 | B3: Mr Hu Lanxiong | C3: =TRIM(B3) -> Mr Hu Lanxiong | D3: 7P/6769 (MMO) | E3: =VLOOKUP(D3, Sheet2!A:C, 3, FALSE) -> Nissan/AD/7P/6769 (MMO) | F3: 0 | G3: 0 | H3: 800000 | I3: Monthly | L3: 2023-05-25 | M3: 2023-07-24 | N3: Running
A4: RENT/2023/0003 | B4: Ko Nay Min Han | C4: =TRIM(B4) -> Ko Nay Min Han | D4: 3H/5929 | E4: =VLOOKUP(D4, Sheet2!A:C, 3, FALSE) -> Nissan/AD/3H/5929 | F4: 0 | G4: 0 | H4: 700000 | I4: Monthly | L4: 2024-06-01 | M4: 2024-06-30 | N4: Running
A5: RENT/2023/0004 | B5: Mr Tong Kai Liang | C5: =TRIM(B5) -> Mr Tong Kai Liang | D5: 1I/4960 | E5: =VLOOKUP(D5, Sheet2!A:C, 3, FALSE) -> Nissan/AD/1I/4960 | F5: 0 | G5: 0 | H5: 700000 | I5: Monthly | L5: 2024-04-29 | M5: 2024-08-28 | N5: Running
A6: RENT/2023/0005 | B6: U Win Naing | C6: =TRIM(B6) -> U Win Naing | D6: 2F/9171 | E6: =VLOOKUP(D6, Sheet2!A:C, 3, FALSE) -> Nissan/AD/2F/9171 | F6: 0 | G6: 0 | H6: 500000 | I6: Monthly | L6: 2024-03-05 | M6: 2024-05-04 | N6: Running
A7: RENT/2023/0006 | B7: Mr Wang Chenghai | C7: =TRIM(B7) -> Mr Wang Chenghai | D7: 4H/8153 | E7: =VLOOKUP(D7, Sheet2!A:C, 3, FALSE) -> Toyota/Belta/4H/8153 | F7: 0 | G7: 0 | H7: 800000 | I7: Monthly | L7: 2024-01-07 | M7: 2024-03-06 | N7: Running
A8: RENT/2023/0007 | B8: Ko Soe Myint Oo | C8: =TRIM(B8) -> Ko Soe Myint Oo | D8: 2Q/1461 (MMO) | E8: =VLOOKUP(D8, Sheet2!A:C, 3, FALSE) -> Suzuki/Ciaz/2Q/1461 (MMO) | F8: 0 | G8: 0 | H8: 1300000 | I8: Monthly | L8: 2024-07-02 | M8: 2024-07-31 | N8: Running
A9: RENT/2023/0008 | B9: Mr Kuo Yuan Yang | C9: =TRIM(B9) -> Mr Kuo Yuan Yang | D9: 2S/2927 | E9: =VLOOKUP(D9, Sheet2!A:C, 3, FALSE) -> Suzuki/Ciaz/2S/2927 | F9: 0 | G9: 0 | H9: 1170000 | I9: Monthly | L9: 45427 | M9: 2025-05-14 | N9: Running
A10: RENT/2023/0009 | B10: Mr Guo Ling | C10: =TRIM(B10) -> Mr Guo Ling | D10: 5Q/8505 (MMO) | E10: =VLOOKUP(D10, Sheet2!A:C, 3, FALSE) -> Honda/Insight/5Q/8505 (MMO) | F10: 0 | G10: 0 | H10: 800000 | I10: Monthly | L10: 2024-03-24 | M10: 2024-06-23 | N10: Running
A11: RENT/2023/0010 | B11: Mr Lu Jian Zhaung | C11: =TRIM(B11) -> Mr Lu Jian Zhaung | D11: 1N/6213 (MMO) | E11: =VLOOKUP(D11, Sheet2!A:C, 3, FALSE) -> Honda/Insight/1N/6213 (MMO) | F11: 0 | G11: 0 | H11: 800000 | I11: Monthly | L11: 2024-04-01 | M11: 2024-06-30 | N11: Running
A12: RENT/2023/0011 | B12: Mr Yu Liang Liang | C12: =TRIM(B12) -> Mr Yu Liang Liang | D12: 1M/9574 (MMO) | E12: =VLOOKUP(D12, Sheet2!A:C, 3, FALSE) -> Honda/Insight/1M/9574 (MMO) | F12: 0 | G12: 0 | H12: 800000 | I12: Monthly | L12: 2024-04-09 | M12: 2024-05-08 | N12: Running
A13: RENT/2023/0012 | B13: Mr Wang Ping | C13: =TRIM(B13) -> Mr Wang Ping | D13: 4H/5781 (MMO) | E13: =VLOOKUP(D13, Sheet2!A:C, 3, FALSE) -> Honda/Insight/4H/5781 (MMO) | F13: 0 | G13: 0 | H13: 800000 | I13: Monthly | L13: 2023-10-03 | M13: 2023-11-02 | N13: Running
A14: RENT/2023/0013 | B14: Mr Xu Yizhi | C14: =TRIM(B14) -> Mr Xu Yizhi | D14: 7K/6305 (MMO) | E14: =VLOOKUP(D14, Sheet2!A:C, 3, FALSE) -> Honda/Insight/7K/6305 (MMO) | F14: 0 | G14: 0 | H14: 800000 | I14: Monthly | L14: 2024-07-02 | M14: 2024-10-01 | N14: Running
A15: RENT/2023/0014 | B15: Mr Pu Yuan Lun | C15: =TRIM(B15) -> Mr Pu Yuan Lun | D15: 9J/5030 (MMO) | E15: =VLOOKUP(D15, Sheet2!A:C, 3, FALSE) -> Honda/Insight/9J/5030 (MMO) | F15: 0 | G15: 0 | H15: 800000 | I15: Monthly | L15: 2024-07-01 | M15: 2024-07-31 | N15: Running
A16: RENT/2023/0015 | B16: Mr Lee /Mr Tang Yong Clun | C16: =TRIM(B16) -> Mr Lee /Mr Tang Yong Clun | D16: 4K/1329 | E16: =VLOOKUP(D16, Sheet2!A:C, 3, FALSE) -> Honda/Insight/4K/1329 | F16: 0 | G16: 0 | H16: 800000 | I16: Monthly | L16: 2024-03-08 | M16: 2024-05-07 | N16: Running
A17: RENT/2023/0016 | B17: U Aung Kyaw | C17: =TRIM(B17) -> U Aung Kyaw | D17: 3J/4642 (MMO) | E17: =VLOOKUP(D17, Sheet2!A:C, 3, FALSE) -> Honda/Insight/3J/4642 (MMO) | F17: 0 | G17: 0 | H17: 800000 | I17: Monthly | L17: 2024-01-27 | M17: 2024-06-26 | N17: Running
A18: RENT/2023/0017 | B18: Ko Aung Kyaw | C18: =TRIM(B18) -> Ko Aung Kyaw | D18: 4L/9873 (MMO) | E18: =VLOOKUP(D18, Sheet2!A:C, 3, FALSE) -> Honda/Insight/4L/9873 (MMO) | F18: 0 | G18: 0 | H18: 300000 | I18: Monthly | L18: 45139 | M18: 2024-02-29 | N18: Running
A19: RENT/2023/0018 | B19: Mr Xie Ming Jian | C19: =TRIM(B19) -> Mr Xie Ming Jian | D19: 9L/9176 (MMO) | E19: =VLOOKUP(D19, Sheet2!A:C, 3, FALSE) -> Honda/Insight/9L/9176 (MMO) | F19: 0 | G19: 0 | H19: 800000 | I19: Monthly | L19: 2024-07-01 | M19: 2024-07-31 | N19: Running
A20: RENT/2023/0019 | B20: Mr Deng Shi Hui | C20: =TRIM(B20) -> Mr Deng Shi Hui | D20: 5H/6646 (MMO) | E20: =VLOOKUP(D20, Sheet2!A:C, 3, FALSE) -> Honda/Insight/5H/6646 (MMO) | F20: 0 | G20: 0 | H20: 800000 | I20: Monthly | L20: 2024-03-21 | M20: 2024-06-20 | N20: Running
A21: RENT/2023/0020 | B21: U Hla Myint | C21: =TRIM(B21) -> U Hla Myint | D21: 9H/5551 (MMO) | E21: =VLOOKUP(D21, Sheet2!A:C, 3, FALSE) -> Honda/Insight/9H/5551 (MMO) | F21: 0 | G21: 0 | H21: 800000 | I21: Monthly | L21: 2024-06-03 | M21: 2024-08-02 | N21: Running
A22: RENT/2023/0021 | B22: Ko Hla Aung Mmo fri | C22: =TRIM(B22) -> Ko Hla Aung Mmo fri | D22: 1L/1050 (MMO) | E22: =VLOOKUP(D22, Sheet2!A:C, 3, FALSE) -> Honda/Insight/1L/1050 (MMO) | F22: 0 | G22: 0 | H22: 800000 | I22: Monthly | L22: 45171 | M22: 2024-07-01 | N22: Running
A23: RENT/2023/0022 | B23: Mr Zhe Jiang | C23: =TRIM(B23) -> Mr Zhe Jiang | D23: 5N/5306 (MMO) | E23: =VLOOKUP(D23, Sheet2!A:C, 3, FALSE) -> Honda/Insight/5N/5306 (MMO) | F23: 0 | G23: 0 | H23: 800000 | I23: Monthly | L23: 45240 | M23: 2024-02-09 | N23: Running
A24: RENT/2023/0023 | B24: Mr Yu Xiang Zhong | C24: =TRIM(B24) -> Mr Yu Xiang Zhong | D24: 9J/7302 (MMO) | E24: =VLOOKUP(D24, Sheet2!A:C, 3, FALSE) -> Honda/Insight/9J/7302 (MMO) | F24: 0 | G24: 0 | H24: 800000 | I24: Monthly | L24: 2023-06-12 | M24: 2023-08-11 | N24: Running
A25: RENT/2023/0024 | B25: Mr Xu Yizhi | C25: =TRIM(B25) -> Mr Xu Yizhi | D25: 5L/4960 (MMO) | E25: =VLOOKUP(D25, Sheet2!A:C, 3, FALSE) -> Honda/Insight/5L/4960 (MMO) | F25: 0 | G25: 0 | H25: 800000 | I25: Monthly | L25: 2024-06-19 | M25: 2024-09-18 | N25: Running
A26: RENT/2023/0025 | B26: Mr XUAN YULONG | C26: =TRIM(B26) -> Mr XUAN YULONG | D26: 6L/8556 (MMO) | E26: =VLOOKUP(D26, Sheet2!A:C, 3, FALSE) -> Honda/Insight/6L/8556 (MMO) | F26: 0 | G26: 0 | H26: 800000 | I26: Monthly | L26: 2024-07-02 | M26: 2024-10-01 | N26: Running
A27: RENT/2023/0026 | B27: Ko Kyaw Kyaw | C27: =TRIM(B27) -> Ko Kyaw Kyaw | D27: 4K/7943 (MMO) | E27: =VLOOKUP(D27, Sheet2!A:C, 3, FALSE) -> Honda/Insight/4K/7943 (MMO) | F27: 0 | G27: 0 | H27: 700000 | I27: Monthly | L27: 2024-05-20 | M27: 2024-06-19 | N27: Running
A28: RENT/2023/0027 | B28: Mr Liu Zhaoyun | C28: =TRIM(B28) -> Mr Liu Zhaoyun | D28: 1K/7482 (MMO) | E28: =VLOOKUP(D28, Sheet2!A:C, 3, FALSE) -> Honda/Insight/1K/7482 (MMO) | F28: 0 | G28: 0 | H28: 800000 | I28: Monthly | L28: 2024-05-02 | M28: 2024-08-01 | N28: Running
A29: RENT/2023/0028 | B29: Ko Kyaw Nyi Nyi Lwin | C29: =TRIM(B29) -> Ko Kyaw Nyi Nyi Lwin | D29: 5L/1648 (MMO) | E29: =VLOOKUP(D29, Sheet2!A:C, 3, FALSE) -> Honda/Insight/5L/1648 (MMO) | F29: 0 | G29: 0 | H29: 800000 | I29: Monthly | L29: 2024-03-24 | M29: 2024-06-23 | N29: Running
A30: RENT/2023/0029 | B30: Mr Xiao Lusheng | C30: =TRIM(B30) -> Mr Xiao Lusheng | D30: 7C/8788 | E30: =VLOOKUP(D30, Sheet2!A:C, 3, FALSE) -> Honda/Insight/7C/8788 | F30: 0 | G30: 0 | H30: 720000 | I30: Monthly | L30: 2024-04-01 | M30: 2024-05-31 | N30: Running
A31: RENT/2023/0030 | B31: Mr Deng Li | C31: =TRIM(B31) -> Mr Deng Li | D31: 7H/8222 | E31: =VLOOKUP(D31, Sheet2!A:C, 3, FALSE) -> Honda/Insight/7H/8222 | F31: 0 | G31: 0 | H31: 800000 | I31: Monthly | L31: 2024-06-08 | M31: 2024-09-07 | N31: Running
A32: RENT/2023/0031 | B32: Mr Mo Enging/Zvan Yip | C32: =TRIM(B32) -> Mr Mo Enging/Zvan Yip | D32: 9J/5405 | E32: =VLOOKUP(D32, Sheet2!A:C, 3, FALSE) -> Honda/Insight/9J/5405 | F32: 0 | G32: 0 | H32: 800000 | I32: Monthly | L32: 2024-03-01 | M32: 2024-06-30 | N32: Running
A33: RENT/2023/0032 | B33: Mr Bai Luokun | C33: =TRIM(B33) -> Mr Bai Luokun | D33: 2J/3021 | E33: =VLOOKUP(D33, Sheet2!A:C, 3, FALSE) -> Honda/Insight/2J/3021 | F33: 0 | G33: 0 | H33: 800000 | I33: Monthly | L33: 2024-06-25 | M33: 2024-09-24 | N33: Running
A34: RENT/2023/0033 | B34: Mr Zeng Jin | C34: =TRIM(B34) -> Mr Zeng Jin | D34: 7K/5798 | E34: =VLOOKUP(D34, Sheet2!A:C, 3, FALSE) -> Honda/Insight/7K/5798 | F34: 0 | G34: 0 | H34: 800000 | I34: Monthly | L34: 2023-04-25 | M34: 2023-05-24 | N34: Running
A35: RENT/2023/0034 | B35: Mr Kway Chi | C35: =TRIM(B35) -> Mr Kway Chi | D35: 7J/5038 | E35: =VLOOKUP(D35, Sheet2!A:C, 3, FALSE) -> Honda/Insight/7J/5038 | F35: 0 | G35: 0 | H35: 800000 | I35: Monthly | L35: 2024-07-17 | M35: 2024-08-16 | N35: Running
... A39: RENT/2023/0038 | B39: Mr Hu Fengbo | C39: =TRIM(B39) -> Mr Hu Fengbo | D39: 5D/3266 | E39: =VLOOKUP(D39, Sheet2!A:C, 3, FALSE) -> Honda/Insight/5D/3266 | F39: 0 | G39: 0 | H39: 800000 | I39: Monthly | L39: 2024-05-29 | M39: 2024-08-28 | N39: Running
A40: RENT/2023/0039 | B40: U Zaw Lin Aung | C40: =TRIM(B40) -> U Zaw Lin Aung | D40: 1L/2491 | E40: =VLOOKUP(D40, Sheet2!A:C, 3, FALSE) -> Honda/Insight/1L/2491 | F40: 0 | G40: 0 | H40: 800000 | I40: Monthly | L40: 45281 | M40: 2024-07-20 | N40: Running
A41: RENT/2023/0040 | B41: Mr Chen Dexiong | C41: =TRIM(B41) -> Mr Chen Dexiong | D41: 1K/7025 | E41: =VLOOKUP(D41, Sheet2!A:C, 3, FALSE) -> Honda/Insight/1K/7025 | F41: 0 | G41: 0 | H41: 800000 | I41: Monthly | L41: 45158 | M41: 2024-03-19 | N41: Running
A42: RENT/2023/0041 | B42: Mr Liu Yi Chung | C42: =TRIM(B42) -> Mr Liu Yi Chung | D42: 5K/8905 | E42: =VLOOKUP(D42, Sheet2!A:C, 3, FALSE) -> Honda/Insight/5K/8905 | F42: 0 | G42: 0 | H42: 800000 | I42: Monthly | L42: 2024-05-18 | M42: 2024-07-17 | N42: Running
A43: RENT/2023/0042 | B43: Mr Jin Zheng Chun/SJ Co., Ltd | C43: =TRIM(B43) -> Mr Jin Zheng Chun/SJ Co., Ltd | D43: 3M/3477 | E43: =VLOOKUP(D43, Sheet2!A:C, 3, FALSE) -> Honda/Insight/3M/3477 | F43: 0 | G43: 0 | H43: 800000 | I43: Monthly | L43: 2024-07-17 | M43: 2024-08-16 | N43: Running
...

Sheet Sheet2
A1: License Plate | B1: Model
A2: 1G/8399 (MMO) | B2: Toyota/Mark II | C2: =CONCATENATE(B2, "/", A2) -> Toyota/Mark II/1G/8399 (MMO)
A3: 1I/4365 | B3: Toyota/Alphard | C3: =CONCATENATE(B3, "/", A3) -> Toyota/Alphard/1I/4365
A4: 1I/4960 | B4: Nissan/AD | C4: =CONCATENATE(B4, "/", A4) -> Nissan/AD/1I/4960
A5: 1I/6866 | B5: Honda/Insight | C5: =CONCATENATE(B5, "/", A5) -> Honda/Insight/1I/6866
A6: 1I/8971 | B6: Honda/Insight | C6: =CONCATENATE(B6, "/", A6) -> Honda/Insight/1I/8971
A7: 1J/4747 | B7: Honda/Insight | C7: =CONCATENATE(B7, "/", A7) -> Honda/Insight/1J/4747
A8: 1K/2555 | B8: Honda/Insight | C8: =CONCATENATE(B8, "/", A8) -> Honda/Insight/1K/2555
A9: 1K/5984 (MMO) | B9: Toyota/Vitz | C9: =CONCATENATE(B9, "/", A9) -> Toyota/Vitz/1K/5984 (MMO)
A10: 1K/7025 | B10: Honda/Insight | C10: =CONCATENATE(B10, "/", A10) -> Honda/Insight/1K/7025
A11: 1K/7482 (MMO) | B11: Honda/Insight | C11: =CONCATENATE(B11, "/", A11) -> Honda/Insight/1K/7482 (MMO)
A12: 1L/1050 (MMO) | B12: Honda/Insight | C12: =CONCATENATE(B12, "/", A12) -> Honda/Insight/1L/1050 (MMO)
A13: 1L/2491 | B13: Honda/Insight | C13: =CONCATENATE(B13, "/", A13) -> Honda/Insight/1L/2491
... A96: 9N/2999 | B96: Nissan/Sunny | C96: =CONCATENATE(B96, "/", A96) -> Nissan/Sunny/9N/2999
